Loaded dependency [python3/3.7.11]: gcc/10.3.0-binutils-2.36.1
Loaded module: python3/3.7.11

Loading python3/3.7.11
  Loading requirement: gcc/10.3.0-binutils-2.36.1
Loaded module: cuda/11.3
Loaded module: cudnn/v8.2.0.53-prod-cuda-11.3
Loaded module: ffmpeg/4.2.2
WARNING: Value for scheme.headers does not match. Please report this to <https://github.com/pypa/pip/issues/9617>
distutils: /zhome/fa/4/127501/.local/include/python3.7m/UNKNOWN
sysconfig: /zhome/fa/4/127501/.local/include/python3.7
WARNING: Additional context:
user = True
home = None
root = None
prefix = None
WARNING: You are using pip version 21.1; however, version 21.3.1 is available.
You should consider upgrading via the '/appl/python/3.7.11/bin/python3 -m pip install --upgrade pip' command.
  WARNING: Value for scheme.headers does not match. Please report this to <https://github.com/pypa/pip/issues/9617>
  distutils: /zhome/fa/4/127501/.local/include/python3.7m/importlib-metadata
  sysconfig: /zhome/fa/4/127501/.local/include/python3.7/importlib-metadata
  WARNING: Additional context:
  user = True
  home = None
  root = None
  prefix = None
WARNING: Value for scheme.headers does not match. Please report this to <https://github.com/pypa/pip/issues/9617>
distutils: /zhome/fa/4/127501/.local/include/python3.7m/UNKNOWN
sysconfig: /zhome/fa/4/127501/.local/include/python3.7
WARNING: Additional context:
user = True
home = None
root = None
prefix = None
WARNING: You are using pip version 21.1; however, version 21.3.1 is available.
You should consider upgrading via the '/appl/python/3.7.11/bin/python3 -m pip install --upgrade pip' command.
WARNING: Value for scheme.headers does not match. Please report this to <https://github.com/pypa/pip/issues/9617>
distutils: /zhome/fa/4/127501/.local/include/python3.7m/UNKNOWN
sysconfig: /zhome/fa/4/127501/.local/include/python3.7
WARNING: Additional context:
user = True
home = None
root = None
prefix = None
WARNING: You are using pip version 21.1; however, version 21.3.1 is available.
You should consider upgrading via the '/appl/python/3.7.11/bin/python3 -m pip install --upgrade pip' command.
Loaded module: cuda/11.3
Loaded module: cudnn/v8.2.0.53-prod-cuda-11.3
WARNING: Value for scheme.headers does not match. Please report this to <https://github.com/pypa/pip/issues/9617>
distutils: /zhome/fa/4/127501/.local/include/python3.7m/UNKNOWN
sysconfig: /zhome/fa/4/127501/.local/include/python3.7
WARNING: Additional context:
user = True
home = None
root = None
prefix = None
WARNING: You are using pip version 21.1; however, version 21.3.1 is available.
You should consider upgrading via the '/appl/python/3.7.11/bin/python3 -m pip install --upgrade pip' command.
  WARNING: Value for scheme.headers does not match. Please report this to <https://github.com/pypa/pip/issues/9617>
  distutils: /zhome/fa/4/127501/.local/include/python3.7m/importlib-metadata
  sysconfig: /zhome/fa/4/127501/.local/include/python3.7/importlib-metadata
  WARNING: Additional context:
  user = True
  home = None
  root = None
  prefix = None
WARNING: Value for scheme.headers does not match. Please report this to <https://github.com/pypa/pip/issues/9617>
distutils: /zhome/fa/4/127501/.local/include/python3.7m/UNKNOWN
sysconfig: /zhome/fa/4/127501/.local/include/python3.7
WARNING: Additional context:
user = True
home = None
root = None
prefix = None
WARNING: You are using pip version 21.1; however, version 21.3.1 is available.
You should consider upgrading via the '/appl/python/3.7.11/bin/python3 -m pip install --upgrade pip' command.
WARNING: Value for scheme.headers does not match. Please report this to <https://github.com/pypa/pip/issues/9617>
distutils: /zhome/fa/4/127501/.local/include/python3.7m/UNKNOWN
sysconfig: /zhome/fa/4/127501/.local/include/python3.7
WARNING: Additional context:
user = True
home = None
root = None
prefix = None
WARNING: You are using pip version 21.1; however, version 21.3.1 is available.
You should consider upgrading via the '/appl/python/3.7.11/bin/python3 -m pip install --upgrade pip' command.
Traceback (most recent call last):
  File "plr.py", line 382, in <module>
    record_and_eval_policy(complete_policy)
  File "plr.py", line 378, in record_and_eval_policy
    imageio.mimsave(f'{FOLDER_NAME}-video-backup-{time.time()}', frames, fps=25)
  File "/zhome/fa/4/127501/.local/lib/python3.7/site-packages/imageio/core/functions.py", line 282, in mimwrite
    with imopen()(uri, "wI", format=format) as file:
  File "/zhome/fa/4/127501/.local/lib/python3.7/site-packages/imageio/core/imopen.py", line 120, in __call__
    raise e
  File "/zhome/fa/4/127501/.local/lib/python3.7/site-packages/imageio/core/imopen.py", line 113, in __call__
    plugin_instance = LegacyPlugin(request, **kwargs)
  File "/zhome/fa/4/127501/.local/lib/python3.7/site-packages/imageio/core/imopen.py", line 218, in __init__
    " in %s mode" % modename
ValueError: Could not find a format to read the specified file in ImageMode.multi_image mode
