Loaded dependency [python3/3.7.11]: gcc/10.3.0-binutils-2.36.1
Loaded module: python3/3.7.11

Loading python3/3.7.11
  Loading requirement: gcc/10.3.0-binutils-2.36.1
Loaded module: cuda/11.3
Loaded module: cudnn/v8.2.0.53-prod-cuda-11.3
Loaded module: ffmpeg/4.2.2
WARNING: Value for scheme.headers does not match. Please report this to <https://github.com/pypa/pip/issues/9617>
distutils: /zhome/fa/4/127501/.local/include/python3.7m/UNKNOWN
sysconfig: /zhome/fa/4/127501/.local/include/python3.7
WARNING: Additional context:
user = True
home = None
root = None
prefix = None
WARNING: You are using pip version 21.1; however, version 21.3.1 is available.
You should consider upgrading via the '/appl/python/3.7.11/bin/python3 -m pip install --upgrade pip' command.
  WARNING: Value for scheme.headers does not match. Please report this to <https://github.com/pypa/pip/issues/9617>
  distutils: /zhome/fa/4/127501/.local/include/python3.7m/importlib-metadata
  sysconfig: /zhome/fa/4/127501/.local/include/python3.7/importlib-metadata
  WARNING: Additional context:
  user = True
  home = None
  root = None
  prefix = None
WARNING: Value for scheme.headers does not match. Please report this to <https://github.com/pypa/pip/issues/9617>
distutils: /zhome/fa/4/127501/.local/include/python3.7m/UNKNOWN
sysconfig: /zhome/fa/4/127501/.local/include/python3.7
WARNING: Additional context:
user = True
home = None
root = None
prefix = None
WARNING: You are using pip version 21.1; however, version 21.3.1 is available.
You should consider upgrading via the '/appl/python/3.7.11/bin/python3 -m pip install --upgrade pip' command.
WARNING: Value for scheme.headers does not match. Please report this to <https://github.com/pypa/pip/issues/9617>
distutils: /zhome/fa/4/127501/.local/include/python3.7m/UNKNOWN
sysconfig: /zhome/fa/4/127501/.local/include/python3.7
WARNING: Additional context:
user = True
home = None
root = None
prefix = None
WARNING: You are using pip version 21.1; however, version 21.3.1 is available.
You should consider upgrading via the '/appl/python/3.7.11/bin/python3 -m pip install --upgrade pip' command.
Loaded module: cuda/11.3
Loaded module: cudnn/v8.2.0.53-prod-cuda-11.3
WARNING: Value for scheme.headers does not match. Please report this to <https://github.com/pypa/pip/issues/9617>
distutils: /zhome/fa/4/127501/.local/include/python3.7m/UNKNOWN
sysconfig: /zhome/fa/4/127501/.local/include/python3.7
WARNING: Additional context:
user = True
home = None
root = None
prefix = None
WARNING: You are using pip version 21.1; however, version 21.3.1 is available.
You should consider upgrading via the '/appl/python/3.7.11/bin/python3 -m pip install --upgrade pip' command.
  WARNING: Value for scheme.headers does not match. Please report this to <https://github.com/pypa/pip/issues/9617>
  distutils: /zhome/fa/4/127501/.local/include/python3.7m/importlib-metadata
  sysconfig: /zhome/fa/4/127501/.local/include/python3.7/importlib-metadata
  WARNING: Additional context:
  user = True
  home = None
  root = None
  prefix = None
WARNING: Value for scheme.headers does not match. Please report this to <https://github.com/pypa/pip/issues/9617>
distutils: /zhome/fa/4/127501/.local/include/python3.7m/UNKNOWN
sysconfig: /zhome/fa/4/127501/.local/include/python3.7
WARNING: Additional context:
user = True
home = None
root = None
prefix = None
WARNING: You are using pip version 21.1; however, version 21.3.1 is available.
You should consider upgrading via the '/appl/python/3.7.11/bin/python3 -m pip install --upgrade pip' command.
WARNING: Value for scheme.headers does not match. Please report this to <https://github.com/pypa/pip/issues/9617>
distutils: /zhome/fa/4/127501/.local/include/python3.7m/UNKNOWN
sysconfig: /zhome/fa/4/127501/.local/include/python3.7
WARNING: Additional context:
user = True
home = None
root = None
prefix = None
WARNING: You are using pip version 21.1; however, version 21.3.1 is available.
You should consider upgrading via the '/appl/python/3.7.11/bin/python3 -m pip install --upgrade pip' command.
Traceback (most recent call last):
  File "plr.py", line 372, in <module>
    complete_policy = create_and_train_network()
  File "plr.py", line 336, in create_and_train_network
    torch.save(policy.state_dict, f'checkpoints/plr/checkpoint-{time.time()}.pt')
  File "/zhome/fa/4/127501/.local/lib/python3.7/site-packages/torch/serialization.py", line 376, in save
    with _open_file_like(f, 'wb') as opened_file:
  File "/zhome/fa/4/127501/.local/lib/python3.7/site-packages/torch/serialization.py", line 230, in _open_file_like
    return _open_file(name_or_buffer, mode)
  File "/zhome/fa/4/127501/.local/lib/python3.7/site-packages/torch/serialization.py", line 211, in __init__
    super(_open_file, self).__init__(open(name, mode))
FileNotFoundError: [Errno 2] No such file or directory: 'checkpoints/plr/checkpoint-1637047482.9568405.pt'
